Workbook
Name a_cr: Design!$C$83
Name A_cust: Design!$C$41
Name A_emp: Design!$C$170
Name A_hold: Design!$C$520
Name A_tyre: Design!$C$310
Name ac_type: Design!$C$40
Name ACN: Design!$C$313
Name aisle_w: Design!$C$52
Name aisle1: Design!$C$245
Name aisle1_b: Design!$C$251
Name aisle2: Design!$C$246
Name aisle2_b: Design!$C$252
Name alpha_cr: Design!$E$649
Name AR_: Design!$E$641
Name AR_HT: Design!$C$61
Name AR_VT: Design!$C$62
Name arm_frac: Design!$C$60
Name B_box: Plot_Data!$AT$1
Name b_HT: Design!$C$275
Name b_VT: Design!$C$280
Name b_w: Design!$C$223
Name beta_cr: Design!$C$88
Name beta_xw: Design!$C$478
Name BFL: Design!$C$387
Name BPR: Design!$C$65
Name brake_g: Design!$C$352
Name bus_frac: Design!$C$26
Name bus_pitch: Design!$C$27
Name c_cabin: Design!$C$528
Name c_cap: Design!$C$530
Name C_cust: Design!$C$42
Name C_emp: Design!$C$171
Name c_fuel: Design!$C$526
Name c_HT: Design!$C$58
Name c_pilot: Design!$C$527
Name c_price: Design!$C$529
Name c_root: Design!$C$227
Name c_tip: Design!$C$228
Name c_VT: Design!$C$59
Name CD_0: Design!$E$643
Name CD_cr: Design!$C$140
Name CD0_est: Design!$C$492
Name cg_aft: Design!$C$448
Name cg_fwd: Design!$C$447
Name cg_MTOM: Design!$D$443
Name chk_ACN: Design!$C$314
Name chk_alt: Design!$C$408
Name chk_BFL: Design!$C$388
Name chk_CD0: Design!$C$494
Name chk_ceil: Design!$C$366
Name chk_clear: Design!$C$341
Name chk_climb: Design!$C$397
Name chk_fin: Design!$C$476
Name chk_fuel: Design!$C$233
Name chk_gear: Design!$C$460
Name chk_hold: Design!$C$523
Name chk_LD: Design!$C$351
Name chk_rot: Design!$C$473
Name chk_SM: Design!$C$456
Name chk_tailfit: Design!$C$463

Sheet Design
A1: AIRCRAFT PRELIMINARY SIZING - change the yellow cells; every value and drawing recalculates
A2: All variables are in columns A-E, colour coded by discipline (key below the results panel). Key results are in G-I. Drawings are to the right (column K onward).
A3: 1. REQUIRED PARAMETERS | B3: Name | C3: Value | D3: Unit | E3: Method / note | G3: KEY RESULTS | H3: Value | I3: Unit
A4: Aspect ratio | B4: AR_ | C4: 9.5 | D4: - | E4: AR [used by: wing sizing, constraints] | G4: Max take-off mass (MTOM) | H4: =(MTOW)*IF(unit_sys="Imperial",2.20462,1) -> 71061.951 | I4: =IF(unit_sys="Imperial","lb","kg") -> kg
A5: Oswald efficiency factor | B5: e_os | C5: 0.8 | D5: - | E5: e [used by: constraints, weight] | G5: Operating empty mass | H5: =(OEW)*IF(unit_sys="Imperial",2.20462,1) -> 35727.3 | I5: =IF(unit_sys="Imperial","lb","kg") -> kg
A6: Zero-lift drag coefficient (clean) | B6: CD_0 | C6: 0.018 | D6: - | E6: CDo [used by: constraints, weight] | G6: Mission fuel (design mission) | H6: =(W_fuel)*IF(unit_sys="Imperial",2.20462,1) -> 21084.651 | I6: =IF(unit_sys="Imperial","lb","kg") -> kg
A7: Maximum payload | B7: PyldMax | C7: 17500 | D7: kg | E7: PyldMax - sets MZFW and the max-payload range point [used by: weight, payload-range] | G7: Design payload | H7: =(W_pl)*IF(unit_sys="Imperial",2.20462,1) -> 14250 | I7: =IF(unit_sys="Imperial","lb","kg") -> kg
A8: Take-off distance available | B8: TODA | C8: 2200 | D8: m | E8: TODA - balanced take-off field length [used by: take-off constraint] | G8: Design wing loading W/S | H8: =(WS_des)*IF(unit_sys="Imperial",0.0208854,1) -> 5281.0085 | I8: =IF(unit_sys="Imperial","lb/ft2","N/m2") -> N/m2
A9: Landing distance available | B9: LDA | C9: 1670 | D9: m | E9: LDA - landing field length [used by: landing constraint] | G9: Design wing loading m/S | H9: =(WS_des/grav)*IF(unit_sys="Imperial",0.204816,1) -> 538.513 | I9: =IF(unit_sys="Imperial","lb/ft2","kg/m2") -> kg/m2
A10: CLmax, take-off configuration | B10: CLmaxTO | C10: 2.1 | D10: - | E10: 'Takeoff' - ASSUMED to mean CLmax in take-off configuration [used by: take-off and climb constraints] | G10: Design thrust-to-weight T/W (SL static) | H10: =TW_des -> 0.27275334 | I10: -
A11: CLmax, landing configuration | B11: CLmaxL | C11: 2.7 | D11: - | E11: 'Landing' - ASSUMED to mean CLmax in landing configuration [used by: landing and climb constraints] | G11: Critical constraint | H11: =crit_con -> Take-off + cruise
A12: Cruise thrust lapse T_cruise / T_SL,static | B12: alpha_cr | C12: 0.22 | D12: - | E12: acr - ASSUMED to be the thrust lapse ratio used in the cruise constraint [used by: cruise constraint, engine sizing] | G12: Wing area S | H12: =(S_ref)*IF(unit_sys="Imperial",10.7639,1) -> 131.95958 | I12: =IF(unit_sys="Imperial","ft2","m2") -> m2
A13: Cruise Mach number | B13: MCR | C13: 0.78 | D13: - | E13: MCR [used by: cruise constraint, wing sweep, weight] | G13: Wing span b | H13: =(b_w)*IF(unit_sys="Imperial",3.28084,1) -> 35.406441 | I13: =IF(unit_sys="Imperial","ft","m") -> m
A14: Thrust-specific fuel consumption in cruise | B14: TSFC_in | C14: 0.6 | D14: 1/h | E14: TSFCcr - pick the unit in column D (1/h = lb/lbf/h = kg/kgf/h) [used by: weight (fuel), payload-range] | G14: Mean aerodynamic chord | H14: =(MAC)*IF(unit_sys="Imperial",3.28084,1) -> 4.174233 | I14: =IF(unit_sys="Imperial","ft","m") -> m
A15: Typical passenger count | B15: PaxTyp | C15: 150 | D15: pax | E15: PaxTyp [used by: fuselage and cabin, weight] | G15: Quarter-chord sweep | H15: =sweep25 -> 26.176952 | I15: deg
A16: Design range with typical payload | B16: RangeTyp | C16: 5000 | D16: km | E16: RangeTyp - pick km or nm in column D [used by: weight (fuel)] | G16: Total SL static thrust | H16: =(T_SL/1000)*IF(unit_sys="Imperial",224.809,1) -> 190.07626 | I16: =IF(unit_sys="Imperial","lbf","kN") -> kN
A17: Typical passenger payload (total) | B17: PayPax | C17: 14250 | D17: kg | E17: Payload_typPax - TOTAL payload of the typical passenger load, in kg (not per passenger) [used by: weight (payload)] | G17: Thrust per engine | H17: =(T_eng/1000)*IF(unit_sys="Imperial",224.809,1) -> 95.038128 | I17: =IF(unit_sys="Imperial","lbf","kN") -> kN
G18: Cruise L/D | H18: =LD_cr -> 17.459659 | I18: -
A19: 2. SECONDARY ASSUMPTIONS (defaults - edit if your brief specifies them) | B19: Name | C19: Value | D19: Unit | E19: Method / note | G19: Fuselage length | H19: =(L_fus)*IF(unit_sys="Imperial",3.28084,1) -> 35.62096 | I19: =IF(unit_sys="Imperial","ft","m") -> m
A20: Cruise altitude | B20: h_cr | C20: 10668 | D20: m | E20: 35 000 ft. ISA atmosphere | G20: Fuselage outer diameter | H20: =(d_fus)*IF(unit_sys="Imperial",3.28084,1) -> 3.98185 | I20: =IF(unit_sys="Imperial","ft","m") -> m
A21: Airport altitude | B21: h_apt | C21: 0 | D21: m | E21: ISA; must be below 11 000 m | G21: Seats abreast x rows | H21: =n_SA&" x "&n_rows -> 6 x 25
A22: Units shown in the key results panel | B22: unit_sys | C22: SI | E22: SI or Imperial (lb, ft, nm, lbf) | G22: Horizontal tail area | H22: =(S_HT)*IF(unit_sys="Imperial",10.7639,1) -> 34.363666 | I22: =IF(unit_sys="Imperial","ft2","m2") -> m2
A23: Empty weight method | B23: ew_mode | C23: Fraction | E23: Fraction = guessed We/W0 (section 4). Build-up = component weights (section 12) fed back into the take-off mass | G23: Vertical tail area | H23: =(S_VT)*IF(unit_sys="Imperial",10.7639,1) -> 26.232977 | I23: =IF(unit_sys="Imperial","ft2","m2") -> m2
A24: Automatic wing placement | B24: wing_auto | C24: Yes | E24: Yes = the wing is positioned to give the target static margin. No = use the manual position below | G24: Main gear: struts x wheels per strut | H24: =n_struts&" x "&n_wps -> 2 x 2
A25: Target static margin at the most aft CG | B25: SM_target | C25: 0.1 | D25: MAC | E25: Used by the automatic wing placement | G25: Main tyre diameter x width | H25: =TEXT(D_tyre,"0.00")&" x "&TEXT(w_tyre,"0.00") -> 1.15 x 0.42 | I25: m
A26: Business-class share of passengers | B26: bus_frac | C26: 0 | D26: - | E26: 0 = single class. Business seats are fewer abreast, at the pitch below | G26: Range with maximum payload | H26: =(R_maxpl)*IF(unit_sys="Imperial",0.539957,1) -> 3590.0086 | I26: =IF(unit_sys="Imperial","nm","km") -> km
A27: Business seat pitch | B27: bus_pitch | C27: 0.97 | D27: m | E27: 38 in | G27: Take-off field length achieved | H27: =(TOFL)*IF(unit_sys="Imperial",3.28084,1) -> 2200 | I27: =IF(unit_sys="Imperial","ft","m") -> m
A28: Number of engines | B28: N_eng | C28: 2 | D28: - | E28: 2, 3 or 4 - drives the one-engine-inoperative climb constraints | G28: Landing field length achieved | H28: =(LFL)*IF(unit_sys="Imperial",3.28084,1) -> 1584.41 | I28: =IF(unit_sys="Imperial","ft","m") -> m
A29: Max landing mass / max take-off mass | B29: ML_ratio | C29: 0.85 | D29: - | E29: Typical 0.75 (long range) to 0.95 (short range) | G29: Service ceiling | H29: =(h_serv)*IF(unit_sys="Imperial",3.28084,1) -> 11258.711 | I29: =IF(unit_sys="Imperial","ft","m") -> m
A30: Residual climb rate at top of climb | B30: ROC_cr | C30: 1.5 | D30: m/s | E30: 300 ft/min; set 0 for a pure level-cruise constraint | G30: Time to climb to cruise altitude | H30: =t_climb -> 18.762342 | I30: min
A31: Landing field coefficient k_L | B31: k_L | C31: 0.107 | D31: kg/m3 | E31: Loftin/Scholz: m_ML/S = k_L * sigma * CLmaxL * LDA (V_app = 1.70*sqrt(LDA)) | G31: Design limit load factor | H31: =n_lim -> 2.5 | I31: -
A32: Take-off field coefficient k_TO | B32: k_TO | C32: 2.34 | D32: m3/kg | E32: Loftin/Scholz: (T/W)/(m/S) = k_TO / (TODA * sigma * CLmaxTO) | G32: Static margin at MTOM | H32: =SM_MTOM -> 0.11294174 | I32: MAC
A33: Landing gear drag increment (landing climb) | B33: dCD0_gear | C33: 0.015 | D33: - | E33: FAR 25 missed approach is flown gear-down | G33: CDo from drag build-up | H33: =CD0_est -> 0.019308435 | I33: -
A34: Fuel fraction: engine start & taxi | B34: ff_taxi | C34: 0.97 | D34: - | E34: Historical regression constant | G34: Empty mass from component build-up | H34: =(W_e_build)*IF(unit_sys="Imperial",2.20462,1) -> 35844.589 | I34: =IF(unit_sys="Imperial","lb","kg") -> kg
A35: Fuel fraction: take-off | B35: ff_TO | C35: 0.985 | D35: - | E35: Historical regression constant | G35: Cost per seat-kilometre | H35: =cost_skm -> 4.5953793 | I35: US cents
A36: Fuel fraction: climb | B36: ff_climb | C36: 0.985 | D36: - | E36: Historical regression constant | G36: Closest real aircraft | H36: =cmp_name -> Airbus A320-200
A37: Fuel fraction: descent | B37: ff_desc | C37: 0.99 | D37: - | E37: Historical regression constant | G37: Balanced field length (Raymer) | H37: =(BFL)*IF(unit_sys="Imperial",3.28084,1) -> 2247.103 | I37: =IF(unit_sys="Imperial","ft","m") -> m
A38: Fuel fraction: reserves / hold | B38: ff_res | C38: 0.95 | D38: - | E38: Historical regression constant | G38: Best initial cruise altitude | H38: =(h_best)*IF(unit_sys="Imperial",3.28084,1) -> 11258.711 | I38: =IF(unit_sys="Imperial","ft","m") -> m
A39: Reserve and trapped fuel factor | B39: k_res | C39: 1.06 | D39: - | E39: Raymer: Wf/W0 = 1.06 * (1 - Mff) | G39: CO2 per seat-kilometre | H39: =co2_skm -> 72.46083 | I39: g
A40: Aircraft type for the empty weight guess | B40: ac_type | C40: Auto | E40: Auto = chosen from PaxTyp and MCR. Or pick a type from the list (table in section 4) | G40: Main tyre pressure | H40: =p_tyre -> 1.0849083 | I40: MPa
...

Sheet Summary
A1: AIRCRAFT DESIGN SUMMARY
A3: =IF(Design!G4="","",Design!G4) -> Max take-off mass (MTOM) | B3: =IF(Design!H4="","",Design!H4) -> 71061.951 | C3: =IF(Design!I4="","",Design!I4) -> kg
A4: =IF(Design!G5="","",Design!G5) -> Operating empty mass | B4: =IF(Design!H5="","",Design!H5) -> 35727.3 | C4: =IF(Design!I5="","",Design!I5) -> kg
A5: =IF(Design!G6="","",Design!G6) -> Mission fuel (design mission) | B5: =IF(Design!H6="","",Design!H6) -> 21084.651 | C5: =IF(Design!I6="","",Design!I6) -> kg
A6: =IF(Design!G7="","",Design!G7) -> Design payload | B6: =IF(Design!H7="","",Design!H7) -> 14250 | C6: =IF(Design!I7="","",Design!I7) -> kg
A7: =IF(Design!G8="","",Design!G8) -> Design wing loading W/S | B7: =IF(Design!H8="","",Design!H8) -> 5281.0085 | C7: =IF(Design!I8="","",Design!I8) -> N/m2
A8: =IF(Design!G9="","",Design!G9) -> Design wing loading m/S | B8: =IF(Design!H9="","",Design!H9) -> 538.513 | C8: =IF(Design!I9="","",Design!I9) -> kg/m2
A9: =IF(Design!G10="","",Design!G10) -> Design thrust-to-weight T/W (SL static) | B9: =IF(Design!H10="","",Design!H10) -> 0.27275334 | C9: =IF(Design!I10="","",Design!I10) -> -
A10: =IF(Design!G11="","",Design!G11) -> Critical constraint | B10: =IF(Design!H11="","",Design!H11) -> Take-off + cruise | C10: =IF(Design!I11="","",Design!I11)
A11: =IF(Design!G12="","",Design!G12) -> Wing area S | B11: =IF(Design!H12="","",Design!H12) -> 131.95958 | C11: =IF(Design!I12="","",Design!I12) -> m2
A12: =IF(Design!G13="","",Design!G13) -> Wing span b | B12: =IF(Design!H13="","",Design!H13) -> 35.406441 | C12: =IF(Design!I13="","",Design!I13) -> m
A13: =IF(Design!G14="","",Design!G14) -> Mean aerodynamic chord | B13: =IF(Design!H14="","",Design!H14) -> 4.174233 | C13: =IF(Design!I14="","",Design!I14) -> m
A14: =IF(Design!G15="","",Design!G15) -> Quarter-chord sweep | B14: =IF(Design!H15="","",Design!H15) -> 26.176952 | C14: =IF(Design!I15="","",Design!I15) -> deg
... A66: =IF(Design!G67="","",Design!G67) -> Tyre pressure and pavement loading | B66: =IF(Design!H67="","",Design!H67) -> OK for major airports (PCN 60-80) | C66: =IF(Design!I67="","",Design!I67)
A68: REQUIREMENT | B68: Required / Achieved | C68: Status
A69: =Design!A621 -> Aspect ratio | B69: =IF(ISNUMBER(Design!B621),IF(Design!B621=INT(Design!B621),TEXT(Design!B621,"#,##0"),TEXT(Design!B621,"0.000")),Design!B621)&" / "&IF(ISNUMBER(Design!C621),IF(Design!C621=INT(Design!C621),TEXT(Design!C621,"#,##0"),TEXT(Design!C621,"0.000")),Design!C621) -> 9.500 / 9.500 | C69: =Design!D621 -> OK
A70: =Design!A622 -> Oswald efficiency factor | B70: =IF(ISNUMBER(Design!B622),IF(Design!B622=INT(Design!B622),TEXT(Design!B622,"#,##0"),TEXT(Design!B622,"0.000")),Design!B622)&" / "&IF(ISNUMBER(Design!C622),IF(Design!C622=INT(Design!C622),TEXT(Design!C622,"#,##0"),TEXT(Design!C622,"0.000")),Design!C622) -> 0.800 / 0.800 | C70: =Design!D622 -> Used as given
A71: =Design!A623 -> Zero-lift drag coefficient | B71: =IF(ISNUMBER(Design!B623),IF(Design!B623=INT(Design!B623),TEXT(Design!B623,"#,##0"),TEXT(Design!B623,"0.000")),Design!B623)&" / "&IF(ISNUMBER(Design!C623),IF(Design!C623=INT(Design!C623),TEXT(Design!C623,"#,##0"),TEXT(Design!C623,"0.000")),Design!C623) -> 0.018 / 0.019 | C71: =Design!D623 -> OK
A72: =Design!A624 -> Maximum payload (kg) | B72: =IF(ISNUMBER(Design!B624),IF(Design!B624=INT(Design!B624),TEXT(Design!B624,"#,##0"),TEXT(Design!B624,"0.000")),Design!B624)&" / "&IF(ISNUMBER(Design!C624),IF(Design!C624=INT(Design!C624),TEXT(Design!C624,"#,##0"),TEXT(Design!C624,"0.000")),Design!C624) -> 17,500 / 17,500 | C72: =Design!D624 -> OK
A73: =Design!A625 -> Take-off distance available (m) | B73: =IF(ISNUMBER(Design!B625),IF(Design!B625=INT(Design!B625),TEXT(Design!B625,"#,##0"),TEXT(Design!B625,"0.000")),Design!B625)&" / "&IF(ISNUMBER(Design!C625),IF(Design!C625=INT(Design!C625),TEXT(Design!C625,"#,##0"),TEXT(Design!C625,"0.000")),Design!C625) -> 2,200 / 2,200 | C73: =Design!D625 -> OK
A74: =Design!A626 -> Landing distance available (m) | B74: =IF(ISNUMBER(Design!B626),IF(Design!B626=INT(Design!B626),TEXT(Design!B626,"#,##0"),TEXT(Design!B626,"0.000")),Design!B626)&" / "&IF(ISNUMBER(Design!C626),IF(Design!C626=INT(Design!C626),TEXT(Design!C626,"#,##0"),TEXT(Design!C626,"0.000")),Design!C626) -> 1,670 / 1584.410 | C74: =Design!D626 -> OK
A75: =Design!A627 -> CLmax, take-off | B75: =IF(ISNUMBER(Design!B627),IF(Design!B627=INT(Design!B627),TEXT(Design!B627,"#,##0"),TEXT(Design!B627,"0.000")),Design!B627)&" / "&IF(ISNUMBER(Design!C627),IF(Design!C627=INT(Design!C627),TEXT(Design!C627,"#,##0"),TEXT(Design!C627,"0.000")),Design!C627) -> 2.100 / 2.100 | C75: =Design!D627 -> OK
A76: =Design!A628 -> CLmax, landing | B76: =IF(ISNUMBER(Design!B628),IF(Design!B628=INT(Design!B628),TEXT(Design!B628,"#,##0"),TEXT(Design!B628,"0.000")),Design!B628)&" / "&IF(ISNUMBER(Design!C628),IF(Design!C628=INT(Design!C628),TEXT(Design!C628,"#,##0"),TEXT(Design!C628,"0.000")),Design!C628) -> 2.700 / 2.700 | C76: =Design!D628 -> OK
A77: =Design!A629 -> Cruise thrust lapse | B77: =IF(ISNUMBER(Design!B629),IF(Design!B629=INT(Design!B629),TEXT(Design!B629,"#,##0"),TEXT(Design!B629,"0.000")),Design!B629)&" / "&IF(ISNUMBER(Design!C629),IF(Design!C629=INT(Design!C629),TEXT(Design!C629,"#,##0"),TEXT(Design!C629,"0.000")),Design!C629) -> 0.220 / 0.198 | C77: =Design!D629 -> OK
A78: =Design!A630 -> Cruise Mach number | B78: =IF(ISNUMBER(Design!B630),IF(Design!B630=INT(Design!B630),TEXT(Design!B630,"#,##0"),TEXT(Design!B630,"0.000")),Design!B630)&" / "&IF(ISNUMBER(Design!C630),IF(Design!C630=INT(Design!C630),TEXT(Design!C630,"#,##0"),TEXT(Design!C630,"0.000")),Design!C630) -> 0.780 / 0.820 | C78: =Design!D630 -> OK
A79: =Design!A631 -> Cruise TSFC | B79: =IF(ISNUMBER(Design!B631),IF(Design!B631=INT(Design!B631),TEXT(Design!B631,"#,##0"),TEXT(Design!B631,"0.000")),Design!B631)&" / "&IF(ISNUMBER(Design!C631),IF(Design!C631=INT(Design!C631),TEXT(Design!C631,"#,##0"),TEXT(Design!C631,"0.000")),Design!C631) -> 0.600 / 0.600 | C79: =Design!D631 -> Used as given
A80: =Design!A632 -> Typical passengers | B80: =IF(ISNUMBER(Design!B632),IF(Design!B632=INT(Design!B632),TEXT(Design!B632,"#,##0"),TEXT(Design!B632,"0.000")),Design!B632)&" / "&IF(ISNUMBER(Design!C632),IF(Design!C632=INT(Design!C632),TEXT(Design!C632,"#,##0"),TEXT(Design!C632,"0.000")),Design!C632) -> 150 / 150 | C80: =Design!D632 -> OK
... A82: =Design!A634 -> Typical passenger payload (kg) | B82: =IF(ISNUMBER(Design!B634),IF(Design!B634=INT(Design!B634),TEXT(Design!B634,"#,##0"),TEXT(Design!B634,"0.000")),Design!B634)&" / "&IF(ISNUMBER(Design!C634),IF(Design!C634=INT(Design!C634),TEXT(Design!C634,"#,##0"),TEXT(Design!C634,"0.000")),Design!C634) -> 14,250 / 14,250 | C82: =Design!D634 -> OK

Sheet Plot_Data
A1: CHART DATA - calculated automatically from the Design sheet. Nothing to edit here. | AS1: Drawing box size (m) | AT1: =1.1*MAX(L_fus,b_w) -> 39.183056
A4: W/S / landing limit | B4: W/S (N/m2) | C4: m/S (kg/m2) | D4: Take-off | E4: 2nd segment OEI | F4: Missed approach OEI | G4: Cruise | H4: Required T/W | K4: Landing W/S | L4: T/W | S4: Station | T4: x (m) | U4: radius (m) | V4: z centre (m) | X4: x centred | Y4: side view z | Z4: top view y | AA4: x from nose | AC4: x centred | AD4: y | AE4: z | AG4: span fraction | AH4: y | AI4: x front | AJ4: z centre | AL4: x centred | AM4: y | AN4: z | AP4: x centred | AQ4: z | AS4: box x | AT4: box y | AV4: seat column | AW4: column used | AX4: lane edge y | AY4: row used | AZ4: row start x | BA4: cabin x | BB4: cabin y | BD4: X | BE4: Y | BF4: Z | BG4: screen u | BH4: screen v | BK4: Legend text | BM4: seat line x | BN4: seat line y | BO4: seat line x centred | BQ4: pilot seat x | BR4: pilot seat y | BT4: lavatory | BU4: used | BV4: front? | BW4: index in zone | BX4: x start | BY4: y low | CA4: outline x | CB4: outline y | CE4: CL clean | CF4: CD clean | CG4: L/D clean | CH4: CL take-off | CI4: CD take-off | CJ4: L/D take-off | CK4: CL landing | CL4: CD landing | CM4: L/D landing | CN4: cruise CD | CO4: cruise CL | CP4: cruise L/D | CR4: altitude m | CS4: T (K) | CT4: density | CU4: speed of sound | CV4: T/W available | CW4: best-climb speed | CX4: rate of climb m/s | CY4: climb time s | CZ4: discriminant | DA4: min speed | DB4: max speed | DC4: min Mach | DD4: max Mach | DE4: cruise alt line x | DF4: cruise alt line y | DG4: cruise Mach | DH4: cruise altitude | DJ4: V (m/s EAS) | DK4: n manoeuvre | DL4: V gust + | DM4: n gust + | DN4: V gust - | DO4: n gust - | DQ4: CG % MAC | DR4: mass kg | DS4: neutral point | DT4: mass | DU4: aft limit | DV4: mass | DX4: fuselage y | DY4: fuselage z | DZ4: surface y | EA4: surface z | EB4: engine y | EC4: engine z | ED4: gear y | EE4: gear z | EG4: skin y | EH4: skin z | EI4: lining y | EJ4: lining z | EK4: floor y | EL4: floor z | EM4: seat y | EN4: seat z | EO4: box | EP4: box | ER4: exit x | ES4: exit y | ET4: galley x | EU4: galley y | EW4: case | EX4: payload kg | EY4: fuel fraction | EZ4: A | GA4: aircraft | GB4: passengers | GC4: MTOM kg | GD4: OEW kg | GE4: wing area m2 | GF4: span m | GG4: length m | GH4: thrust per engine kN | GI4: engines | GJ4: range km | GK4: distance score | GZ4: wing placement solver | HA4: trial 1 | HB4: trial 2 | HC4: wing position needed | HF4: W0 guess | HG4: wing area | HH4: span | HI4: root chord | HJ4: MAC | HK4: wing | HL4: tails | HM4: fuselage | HN4: gear | HO4: engines | HP4: systems | HQ4: empty mass | HR4: W0 new | HT4: seat column | HU4: column used | HV4: lane edge y | HW4: row used | HX4: row start x | HY4: seat line x | HZ4: seat line y | IA4: seat line x centred | IC4: tank x centred | ID4: tank y
A5: =10/50 -> 0.2 | B5: =A5*WS_max -> 1113.2578 | C5: =B5/grav -> 113.52071 | D5: =TO_slope*B5 -> 0.0574975 | E5: =TW_2 -> 0.21941554 | F5: =TW_MA -> 0.21104328 | G5: =beta_cr/alpha_cr*(q_cr*CD_0/(beta_cr*B5)+K_ind*beta_cr*B5/q_cr+ROC_cr/V_cr) -> 0.79248732 | H5: =MAX(D5:G5) -> 0.79248732 | K5: =WS_max -> 5566.2892 | L5: 0 | S5: nose 0.00 | T5: =0*nose_len -> 0 | U5: =d_fus/2*SQRT(1-(1-0)^2) -> 0 | V5: =-0.3*(d_fus/2-U5) -> -0.5972775 | X5: =T5-L_fus/2 -> -17.81048 | Y5: =V5+1*U5 -> -0.5972775 | Z5: =1*U5 -> 0 | AA5: =T5 -> 0 | AC5: =x_wLE0-L_fus/2 -> -7.3048467 | AD5: 0 | AE5: =z_w0 -> -1.194555 | AG5: =eta_in -> 0.34 | AH5: =AG5*b_w/2 -> 6.0190949 | AI5: =IF(AG5=0,L_fus-tail_len-0.2*L_nac,x_wLE0+ABS(AH5)*TAN(RADIANS(sweepLE))-0.8*L_nac) -> 10.385503 | AJ5: =IF(AG5=0,z_VT0+0.55*D_nac,z_w0+ABS(AH5)*TAN(RADIANS(dihedral))-0.6*D_nac) -> -2.0075068 | AL5: =AI5+0*L_nac-L_fus/2 -> -7.4249768 | AM5: =AH5+-1*D_nac/2 -> 4.9027996 | AN5: =AJ5+-1*D_nac/2 -> -3.1238022 | AP5: =x_main-L_fus/2+0*D_tyre/2 -> -0.30456748 | AQ5: =-h_cg+D_tyre/2+1*D_tyre/2 -> -2.5108116 | AS5: =-1*B_box/2 -> -19.591528 | AT5: =-1*B_box/2 -> -19.591528 | AV5: 0 | AW5: =MIN(AV5,n_SA-1) -> 0 | AX5: =-w_cabin/2+0.025+(1)*(AW5*seat_w+aisle_w*((AW5>=aisle1)+(AW5>=aisle2))) -> -1.84 | AY5: =MAX(0,MIN(0,n_rows-1)) -> 0 | AZ5: =x_eco0+AY5*(seat_pitch) -> 6.5 | BA5: =nose_len+0*L_cabin -> 4 | BB5: =-1*w_cabin/2 -> -1.865 | BC5: =BA5-L_fus/2 -> -13.81048 | BD5: =T5-L_fus/2 -> -17.81048 | BE5: =U5*1 -> 0 | BF5: =V5+U5*0 -> -0.5972775 | BG5: =BD5*COS(RADIANS(view_az))+BE5*SIN(RADIANS(view_az)) -> -13.643619 | BH5: =BF5*COS(RADIANS(view_el))+(BE5*COS(RADIANS(view_az))-BD5*SIN(RADIANS(view_az)))*SIN(RADIANS(view_el)) -> 4.296967 | BK5: ="Fuselage: L = "&TEXT(L_fus,"0.0")&" m, d = "&TEXT(d_fus,"0.00")&" m" -> Fuselage: L = 35.6 m, d = 3.98 m | BM5: =$AZ$5+0.2*(seat_pitch)*($AY$5*n_SA+$AW$5<pax_e) -> 6.662 | BN5: =$AX$5 -> -1.84 | BO5: =BM5-L_fus/2 -> -11.14848 | BQ5: =0.5*nose_len+0*MIN(0.6,0.2*nose_len) -> 2 | BR5: =-1*MIN(0.55,0.2*d_fus)+-1*MIN(0.5,0.25*d_fus)/2 -> -0.8 | BT5: 0 | BU5: =MIN(BT5,n_lav-1) -> 0 | BV5: =IF(BU5<n_lav_front,1,0) -> 1 | BW5: =IF(BV5=1,BU5,BU5-n_lav_front) -> 0 | BX5: =IF(BV5=1,nose_len,x_seat_end+door_len)+INT(BW5/lav_slots)*lav_len -> 4 | BY5: =CHOOSE(MOD(BW5,lav_slots)+1,-w_cabin/2,w_cabin/2-lav_w,-lav_w/2) -> -1.865 | CA5: =$BX$5+0*lav_len -> 4 | CB5: =$BY$5+0*lav_w -> -1.865 | CE5: =0/24*CLmax_c -> 0 | CF5: =CD_0+K_ind*CE5^2 -> 0.018 | CG5: =CE5/CF5 -> 0 | CH5: =0/24*CLmaxTO -> 0 | CI5: =CD_0+dCD0_f2+K_ind*CH5^2 -> 0.035916667 | CJ5: =CH5/CI5 -> 0 | CK5: =0/24*CLmaxL -> 0 | CL5: =CD_0+dCD0_fMA+dCD0_gear+K_ind*CK5^2 -> 0.057881657 | CM5: =CK5/CL5 -> 0 | CN5: =CD_cr -> 0.028034333 | CO5: =CL_cr -> 0.4894699 | CP5: =LD_cr -> 17.459659 | CR5: =0/28*h_abs -> 0 | CS5: =IF(CR5<=11000,288.15-0.0065*CR5,216.65) -> 288.15 | CT5: =IF(CR5<=11000,rho_SL*(CS5/288.15)^4.25588,0.36392*EXP(-(CR5-11000)/6341.62)) -> 1.225 | CU5: =SQRT(1.4*287.053*CS5) -> 340.29407 | CV5: =TW_p*(CT5/rho_SL)^lapse_n -> 0.28981835 | CW5: =MIN(M_MO*CU5,SQRT(CV5*WS_p*(1+SQRT(1+3/(LD_max^2*CV5^2)))/(3*CT5*CD_0))) -> 211.40613 | CX5: =MAX(0,CW5*(CV5-0.5*CT5*CW5^2*CD_0/WS_p-K_ind*WS_p/(0.5*CT5*CW5^2))) -> 38.702804 | CY5: =IF(CR5>=h_cr,0,(MIN(CR6,h_cr)-CR5)/MAX(0.05,(CX5+CX6)/2)) -> 10.904192 | CZ5: =MAX(0,CV5^2-4*CD_0*K_ind) -> 0.080979107 | DA5: =MAX(SQRT(2*WS_p/(CT5*CLmax_c)),SQRT(2*WS_p*(CV5-SQRT(CZ5))/(2*CD_0)/CT5)) -> 73.549861 | DB5: =MAX(DA5,MIN(M_MO*CU5,SQRT(2*WS_p*(CV5+SQRT(CZ5))/(2*CD_0)/CT5))) -> 279.04113 | DC5: =DA5/CU5 -> 0.21613618 | DD5: =DB5/CU5 -> 0.82 | DE5: 0 | DF5: =h_cr -> 10668 | DG5: =MCR -> 0.78 | DH5: =h_cr -> 10668 | DJ5: =0/10*V_A -> 0 | DK5: =(0/10*V_A/V_S1)^2 -> 0 | DL5: 0 | DM5: 1 | DN5: 0 | DO5: 1 | DQ5: =Design!$D$441 -> 0.43553093 | DR5: =Design!$B$441 -> 35727.3 | DS5: =x_np -> 0.57069573 | DT5: =0.95*OEW -> 33940.935 | DU5: =x_np-0.05 -> 0.52069573 | DV5: =0.95*OEW -> 33940.935 | DX5: =d_fus/2*1 -> 1.990925 | DY5: =d_fus/2*0 -> 0 | DZ5: =-b_w/2 -> -17.70322 | EA5: =z_w0+b_w/2*TAN(RADIANS(dihedral)) -> 0.35427609 | EB5: =$AH$5+D_nac/2*1 -> 7.1353903 | EC5: =$AJ$5+D_nac/2*0 -> -2.0075068 | ED5: =-track/2+0*2.2*w_tyre/2 -> -3.5406441 | EE5: =z_w0+track/2*TAN(RADIANS(dihedral)) -> -0.88478878 | EG5: =d_fus/2*1 -> 1.990925 | EH5: =d_fus/2*0 -> 0 | EI5: =w_cabin/2*1 -> 1.865 | EJ5: =w_cabin/2*0 -> 0 | EK5: =-1*SQRT(MAX(0,(w_cabin/2)^2-(z_floor)^2)) -> -1.7658497 | EL5: =z_floor -> -0.6 | EM5: =$AX$5+0.05*seat_w -> -1.8135 | EN5: =z_floor+0 -> -0.6 | EO5: =-1*0.6*d_fus -> -2.38911 | EP5: =-1*0.6*d_fus -> -2.38911 | ER5: =IF(0<n_door,x_door_f+IF(n_door>1,0/(n_door-1),0)*(x_door_r-x_door_f),IF(0<n_door+n_overwing,x_ac_w+(0-n_door-(n_overwing-1)/2)*seat_pitch,x_door_f)) -> 5.75 | ES5: =-1*w_cabin/2 -> -1.865 | ET5: =x_seat0-door_len+0*0.6 -> 5 | EU5: =w_cabin/2-gal_w+0*gal_w -> 0.265 | EW5: Range x 0.9 | EX5: =W_pl -> 14250 | EY5: =k_res*(1-ff_fixed*EXP(-Range_km*0.9*1000*TSFC_s*1/(V_cr*LD_cr))) -> 0.2807936 | EZ5: =A_emp -> 0.97 | FA5: =MTOW_frac -> 71061.951 | FB5: =IF(1-$EY5-$EZ5*FA5^C_emp>0.02,(W_crew+$EX5)/(1-$EY5-$EZ5*FA5^C_emp),FA5) -> 65990.314 | FC5: =IF(1-$EY5-$EZ5*FB5^C_emp>0.02,(W_crew+$EX5)/(1-$EY5-$EZ5*FB5^C_emp),FB5) -> 66650.711 | FD5: =IF(1-$EY5-$EZ5*FC5^C_emp>0.02,(W_crew+$EX5)/(1-$EY5-$EZ5*FC5^C_emp),FC5) -> 66560.958 | FE5: =IF(1-$EY5-$EZ5*FD5^C_emp>0.02,(W_crew+$EX5)/(1-$EY5-$EZ5*FD5^C_emp),FD5) -> 66573.086 | FF5: =IF(1-$EY5-$EZ5*FE5^C_emp>0.02,(W_crew+$EX5)/(1-$EY5-$EZ5*FE5^C_emp),FE5) -> 66571.446 | FG5: =IF(1-$EY5-$EZ5*FF5^C_emp>0.02,(W_crew+$EX5)/(1-$EY5-$EZ5*FF5^C_emp),FF5) -> 66571.668 | FH5: =IF(1-$EY5-$EZ5*FG5^C_emp>0.02,(W_crew+$EX5)/(1-$EY5-$EZ5*FG5^C_emp),FG5) -> 66571.638 | FI5: =IF(1-$EY5-$EZ5*FH5^C_emp>0.02,(W_crew+$EX5)/(1-$EY5-$EZ5*FH5^C_emp),FH5) -> 66571.642 | ... FY5: =IF(1-$EY5-$EZ5*FX5^C_emp>0.02,(W_crew+$EX5)/(1-$EY5-$EZ5*FX5^C_emp),FX5) -> 66571.641 | GA5: Cessna Citation CJ3 | GB5: 7 | GC5: 6291 | GD5: 3850 | GE5: 27.3 | GF5: 16.26 | GG5: 15.59 | GH5: 12.5 | GI5: 2 | GJ5: 3480 | GK5: =ABS(LN(GC5/MTOW))+ABS(LN(MAX(1,GB5)/MAX(1,PaxTyp))) -> 5.4891571 | GZ5: wing position / length | HA5: 0.38 | HB5: 0.54 | HF5: =MTOW_frac -> 71061.951 | HG5: =HF5*grav/WS_des -> 131.95958 | HH5: =SQRT(AR_*HG5) -> 35.406441 | HI5: =2*HG5/(HH5*(1+taper)) -> 5.96319 | HJ5: =2/3*HI5*(1+taper+taper^2)/(1+taper) -> 4.174233 | HK5: =49*MAX(0.5*HG5,HG5-d_fus*HI5*(1-(1-taper)*d_fus/(2*HH5))) -> 5351.6052 | HL5: =27*(c_HT*HJ5*HG5/L_tail+c_VT*HH5*HG5/L_tail) -> 1636.1094 | HM5: =24*S_wet_fus -> 9147.0379 | HN5: =0.043*HF5 -> 3055.6639 | HO5: =1.3*N_eng*14.7*(TW_des*HF5*grav/N_eng/1000)^1.1*EXP(-0.045*BPR) -> 4573.6411 | HP5: =0.17*HF5 -> 12080.532 | HQ5: =SUM(HK5:HP5) -> 35844.589 | HR5: =IF(fuel_frac<0.95,MIN(100*MTOW_frac,(W_crew+W_pl+HQ5)/(1-fuel_frac)),HF5) -> 71889.899 | HT5: 0 | HU5: =MIN(HT5,n_SA_b-1) -> 0 | HV5: =-w_cabin/2+0.025+(n_rows_b>0)*(HU5*seat_w_b+aisle_w*((HU5>=aisle1_b)+(HU5>=aisle2_b))) -> -1.84 | HW5: =MAX(0,MIN(0,n_rows_b-1)) -> 0 | HX5: =x_seat0+HW5*(bus_pitch*(n_rows_b>0)) -> 6.5 | HY5: =$HX$5+0.2*(bus_pitch*(n_rows_b>0))*($HW$5*n_SA_b+$HU$5<pax_b) -> 6.5 | HZ5: =$HV$5 -> -1.84 | IA5: =HY5-L_fus/2 -> -11.31048 | IC5: =x_wLE0+(d_fus/2)*TAN(RADIANS(sweepLE))-L_fus/2+0.15*c_root*(1-(1-taper)*2*(d_fus/2)/b_w) -> -5.3814091 | ID5: =1*d_fus/2 -> 1.990925
A6: =11/50 -> 0.22 | B6: =A6*WS_max -> 1224.5836 | C6: =B6/grav -> 124.87278 | D6: =TO_slope*B6 -> 0.06324725 | E6: =TW_2 -> 0.21941554 | F6: =TW_MA -> 0.21104328 | G6: =beta_cr/alpha_cr*(q_cr*CD_0/(beta_cr*B6)+K_ind*beta_cr*B6/q_cr+ROC_cr/V_cr) -> 0.72649435 | H6: =MAX(D6:G6) -> 0.72649435 | K6: =WS_max -> 5566.2892 | L6: 0.8 | S6: nose 0.02 | T6: =0.02*nose_len -> 0.08 | U6: =d_fus/2*SQRT(1-(1-0.02)^2) -> 0.39618907 | V6: =-0.3*(d_fus/2-U6) -> -0.47842078 | X6: =T6-L_fus/2 -> -17.73048 | Y6: =V6+1*U6 -> -0.082231706 | Z6: =1*U6 -> 0.39618907 | AA6: =T6 -> 0.08 | AC6: =x_wLE0+b_w/2*TAN(RADIANS(sweepLE))-L_fus/2 -> 2.515472 | AD6: =b_w/2 -> 17.70322 | AE6: =z_w0+b_w/2*TAN(RADIANS(dihedral)) -> 0.35427609 | AG6: =-eta_in -> -0.34 | AH6: =AG6*b_w/2 -> -6.0190949 | AI6: =IF(AG6=0,L_fus-tail_len-0.2*L_nac,x_wLE0+ABS(AH6)*TAN(RADIANS(sweepLE))-0.8*L_nac) -> 10.385503 | AJ6: =IF(AG6=0,z_VT0+0.55*D_nac,z_w0+ABS(AH6)*TAN(RADIANS(dihedral))-0.6*D_nac) -> -2.0075068 | AL6: =AI5+1*L_nac-L_fus/2 -> -3.1011787 | AM6: =AH5+-1*D_nac/2 -> 4.9027996 | AN6: =AJ5+-1*D_nac/2 -> -3.1238022 | AP6: =x_main-L_fus/2+-0.5*D_tyre/2 -> -0.59269007 | AQ6: =-h_cg+D_tyre/2+0.86603*D_tyre/2 -> -2.5880112 | AS6: =1*B_box/2 -> 19.591528 | AT6: =1*B_box/2 -> 19.591528 | AV6: 1 | AW6: =MIN(AV6,n_SA-1) -> 1 | AX6: =-w_cabin/2+0.025+(1)*(AW6*seat_w+aisle_w*((AW6>=aisle1)+(AW6>=aisle2))) -> -1.31 | AY6: =MAX(0,MIN(1,n_rows-1)) -> 1 | AZ6: =x_eco0+AY6*(seat_pitch) -> 7.31 | BA6: =nose_len+1*L_cabin -> 29.25 | BB6: =-1*w_cabin/2 -> -1.865 | BC6: =BA6-L_fus/2 -> 11.43952 | BD6: =T6-L_fus/2 -> -17.73048 | BE6: =U6*1 -> 0.39618907 | BF6: =V6+U6*0 -> -0.47842078 | BG6: =BD6*COS(RADIANS(view_az))+BE6*SIN(RADIANS(view_az)) -> -13.32767 | BH6: =BF6*COS(RADIANS(view_el))+(BE6*COS(RADIANS(view_az))-BD6*SIN(RADIANS(view_az)))*SIN(RADIANS(view_el)) -> 4.5112195 | BK6: ="Wing: S = "&TEXT(S_ref,"0.0")&" m2, b = "&TEXT(b_w,"0.0")&" m, c/4 sweep "&TEXT(sweep25,"0")&" deg" -> Wing: S = 132.0 m2, b = 35.4 m, c/4 sweep 26 deg | BM6: =$AZ$5+0.2*(seat_pitch)*($AY$5*n_SA+$AW$5<pax_e) -> 6.662 | BN6: =$AX$5+seat_w*($AY$5*n_SA+$AW$5<pax_e) -> -1.31 | BO6: =BM6-L_fus/2 -> -11.14848 | BQ6: =0.5*nose_len+1*MIN(0.6,0.2*nose_len) -> 2.6 | BR6: =-1*MIN(0.55,0.2*d_fus)+-1*MIN(0.5,0.25*d_fus)/2 -> -0.8 | BT6: 1 | BU6: =MIN(BT6,n_lav-1) -> 1 | BV6: =IF(BU6<n_lav_front,1,0) -> 0 | BW6: =IF(BV6=1,BU6,BU6-n_lav_front) -> 0 | BX6: =IF(BV6=1,nose_len,x_seat_end+door_len)+INT(BW6/lav_slots)*lav_len -> 28.25 | BY6: =CHOOSE(MOD(BW6,lav_slots)+1,-w_cabin/2,w_cabin/2-lav_w,-lav_w/2) -> -1.865 | CA6: =$BX$5+1*lav_len -> 5 | CB6: =$BY$5+0*lav_w -> -1.865 | CE6: =1/24*CLmax_c -> 0.0625 | CF6: =CD_0+K_ind*CE6^2 -> 0.018163605 | CG6: =CE6/CF6 -> 3.4409469 | CH6: =1/24*CLmaxTO -> 0.0875 | CI6: =CD_0+dCD0_f2+K_ind*CH6^2 -> 0.036237332 | CJ6: =CH6/CI6 -> 2.4146369 | CK6: =1/24*CLmaxL -> 0.1125 | CL6: =CD_0+dCD0_fMA+dCD0_gear+K_ind*CK6^2 -> 0.058411737 | CM6: =CK6/CL6 -> 1.9259828 | CR6: =1/28*h_abs -> 409.47917 | CS6: =IF(CR6<=11000,288.15-0.0065*CR6,216.65) -> 285.48839 | CT6: =IF(CR6<=11000,rho_SL*(CS6/288.15)^4.25588,0.36392*EXP(-(CR6-11000)/6341.62)) -> 1.1775629 | CU6: =SQRT(1.4*287.053*CS6) -> 338.71879 | CV6: =TW_p*(CT6/rho_SL)^lapse_n -> 0.27539695 | CW6: =MIN(M_MO*CU6,SQRT(CV6*WS_p*(1+SQRT(1+3/(LD_max^2*CV6^2)))/(3*CT6*CD_0))) -> 210.46976 | CX6: =MAX(0,CW6*(CV6-0.5*CT6*CW6^2*CD_0/WS_p-K_ind*WS_p/(0.5*CT6*CW6^2))) -> 36.402107 | CY6: =IF(CR6>=h_cr,0,(MIN(CR7,h_cr)-CR6)/MAX(0.05,(CX6+CX7)/2)) -> 11.59942 | CZ6: =MAX(0,CV6^2-4*CD_0*K_ind) -> 0.072827914 | DA6: =MAX(SQRT(2*WS_p/(CT6*CLmax_c)),SQRT(2*WS_p*(CV6-SQRT(CZ6))/(2*CD_0)/CT6)) -> 75.016679 | DB6: =MAX(DA6,MIN(M_MO*CU6,SQRT(2*WS_p*(CV6+SQRT(CZ6))/(2*CD_0)/CT6))) -> 277.74941 | DC6: =DA6/CU6 -> 0.22147186 | DD6: =DB6/CU6 -> 0.82 | DE6: =ROC_SL -> 38.702804 | DF6: =h_cr -> 10668 | DJ6: =1/10*V_A -> 11.987531 | DK6: =(1/10*V_A/V_S1)^2 -> 0.025 | DL6: =V_C -> 128.75511 | DM6: =n_gC -> 1.8374317 | DN6: =V_C -> 128.75511 | DO6: =2-n_gC -> 0.16256831 | DQ6: =Design!$D$442 -> 0.46102527 | DR6: =Design!$B$442 -> 49977.3 | DS6: =x_np -> 0.57069573 | DT6: =1.03*MTOW -> 73193.809 | DU6: =x_np-0.05 -> 0.52069573 | DV6: =1.03*MTOW -> 73193.809 | DX6: =d_fus/2*0.96593 -> 1.9230942 | DY6: =d_fus/2*0.25882 -> 0.51529121 | DZ6: 0 | EA6: =z_w0 -> -1.194555 | EB6: =$AH$5+D_nac/2*0.86603 -> 6.9858402 | EC6: =$AJ$5+D_nac/2*0.5 -> -1.4493592 | ED6: =-track/2+0*2.2*w_tyre/2 -> -3.5406441 | EE6: =-h_cg+D_tyre -> -2.5108116 | EG6: =d_fus/2*0.98481 -> 1.9606828 | EH6: =d_fus/2*0.17365 -> 0.34572413 | EI6: =w_cabin/2*0.98481 -> 1.8366706 | EJ6: =w_cabin/2*0.17365 -> 0.32385725 | EK6: =1*SQRT(MAX(0,(w_cabin/2)^2-(z_floor)^2)) -> 1.7658497 | EL6: =z_floor -> -0.6 | EM6: =$AX$5+0.05*seat_w -> -1.8135 | EN6: =z_floor+1.1 -> 0.5 | EO6: =1*0.6*d_fus -> 2.38911 | EP6: =1*0.6*d_fus -> 2.38911 | ER6: =IF(0<n_door,x_door_f+IF(n_door>1,0/(n_door-1),0)*(x_door_r-x_door_f),IF(0<n_door+n_overwing,x_ac_w+(0-n_door-(n_overwing-1)/2)*seat_pitch,x_door_f)) -> 5.75 | ES6: =1*w_cabin/2 -> 1.865 | ET6: =x_seat0-door_len+1*0.6 -> 5.6 | EU6: =w_cabin/2-gal_w+0*gal_w -> 0.265 | EW6: Range x 1.1 | EX6: =W_pl -> 14250 | EY6: =k_res*(1-ff_fixed*EXP(-Range_km*1.1*1000*TSFC_s*1/(V_cr*LD_cr))) -> 0.31229742 | EZ6: =A_emp -> 0.97 | FA6: =MTOW_frac -> 71061.951 | FB6: =IF(1-$EY6-$EZ6*FA6^C_emp>0.02,(W_crew+$EX6)/(1-$EY6-$EZ6*FA6^C_emp),FA6) -> 76847.373 | FC6: =IF(1-$EY6-$EZ6*FB6^C_emp>0.02,(W_crew+$EX6)/(1-$EY6-$EZ6*FB6^C_emp),FB6) -> 75925.538 | FD6: =IF(1-$EY6-$EZ6*FC6^C_emp>0.02,(W_crew+$EX6)/(1-$EY6-$EZ6*FC6^C_emp),FC6) -> 76065.95 | FE6: =IF(1-$EY6-$EZ6*FD6^C_emp>0.02,(W_crew+$EX6)/(1-$EY6-$EZ6*FD6^C_emp),FD6) -> 76044.413 | FF6: =IF(1-$EY6-$EZ6*FE6^C_emp>0.02,(W_crew+$EX6)/(1-$EY6-$EZ6*FE6^C_emp),FE6) -> 76047.713 | FG6: =IF(1-$EY6-$EZ6*FF6^C_emp>0.02,(W_crew+$EX6)/(1-$EY6-$EZ6*FF6^C_emp),FF6) -> 76047.207 | FH6: =IF(1-$EY6-$EZ6*FG6^C_emp>0.02,(W_crew+$EX6)/(1-$EY6-$EZ6*FG6^C_emp),FG6) -> 76047.284 | FI6: =IF(1-$EY6-$EZ6*FH6^C_emp>0.02,(W_crew+$EX6)/(1-$EY6-$EZ6*FH6^C_emp),FH6) -> 76047.273 | ... FY6: =IF(1-$EY6-$EZ6*FX6^C_emp>0.02,(W_crew+$EX6)/(1-$EY6-$EZ6*FX6^C_emp),FX6) -> 76047.274 | GA6: Embraer ERJ 145 | GB6: 50 | GC6: 22000 | GD6: 12114 | GE6: 51.2 | GF6: 20.04 | GG6: 29.87 | GH6: 33.7 | GI6: 2 | GJ6: 2870 | GK6: =ABS(LN(GC6/MTOW))+ABS(LN(MAX(1,GB6)/MAX(1,PaxTyp))) -> 2.2711219 | GZ6: leading edge of MAC | HA6: =HA5*L_fus-0.25*MAC -> 12.492407 | HB6: =HB5*L_fus-0.25*MAC -> 18.19176 | HF6: =HR5 -> 71889.899 | HG6: =HF6*grav/WS_des -> 133.49705 | HH6: =SQRT(AR_*HG6) -> 35.612105 | HI6: =2*HG6/(HH6*(1+taper)) -> 5.9978282 | HJ6: =2/3*HI6*(1+taper+taper^2)/(1+taper) -> 4.1984797 | HK6: =49*MAX(0.5*HG6,HG6-d_fus*HI6*(1-(1-taper)*d_fus/(2*HH6))) -> 5420.183 | HL6: =27*(c_HT*HJ6*HG6/L_tail+c_VT*HH6*HG6/L_tail) -> 1664.7862 | HM6: =24*S_wet_fus -> 9147.0379 | HN6: =0.043*HF6 -> 3091.2657 | HO6: =1.3*N_eng*14.7*(TW_des*HF6*grav/N_eng/1000)^1.1*EXP(-0.045*BPR) -> 4632.2918 | HP6: =0.17*HF6 -> 12221.283 | HQ6: =SUM(HK6:HP6) -> 36176.847 | HR6: =IF(fuel_frac<0.95,MIN(100*MTOW_frac,(W_crew+W_pl+HQ6)/(1-fuel_frac)),HF6) -> 72362.332 | HT6: 1 | HU6: =MIN(HT6,n_SA_b-1) -> 1 | HV6: =-w_cabin/2+0.025+(n_rows_b>0)*(HU6*seat_w_b+aisle_w*((HU6>=aisle1_b)+(HU6>=aisle2_b))) -> -1.84 | HW6: =MAX(0,MIN(1,n_rows_b-1)) -> 0 | HX6: =x_seat0+HW6*(bus_pitch*(n_rows_b>0)) -> 6.5 | HY6: =$HX$5+0.2*(bus_pitch*(n_rows_b>0))*($HW$5*n_SA_b+$HU$5<pax_b) -> 6.5 | HZ6: =$HV$5+seat_w_b*($HW$5*n_SA_b+$HU$5<pax_b) -> -1.84 | IA6: =HY6-L_fus/2 -> -11.31048 | IC6: =x_wLE0+(0.85*b_w/2)*TAN(RADIANS(sweepLE))-L_fus/2+0.15*c_root*(1-(1-taper)*2*(0.85*b_w/2)/b_w) -> 1.3666727 | ID6: =1*0.85*b_w/2 -> 15.047737
A7: =12/50 -> 0.24 | B7: =A7*WS_max -> 1335.9094 | C7: =B7/grav -> 136.22485 | D7: =TO_slope*B7 -> 0.068997 | E7: =TW_2 -> 0.21941554 | F7: =TW_MA -> 0.21104328 | G7: =beta_cr/alpha_cr*(q_cr*CD_0/(beta_cr*B7)+K_ind*beta_cr*B7/q_cr+ROC_cr/V_cr) -> 0.67180832 | H7: =MAX(D7:G7) -> 0.67180832 | S7: nose 0.07 | T7: =0.07*nose_len -> 0.28 | U7: =d_fus/2*SQRT(1-(1-0.07)^2) -> 0.73178344 | V7: =-0.3*(d_fus/2-U7) -> -0.37774247 | X7: =T7-L_fus/2 -> -17.53048 | Y7: =V7+1*U7 -> 0.35404097 | Z7: =1*U7 -> 0.73178344 | AA7: =T7 -> 0.28 | AC7: =x_wLE0+b_w/2*TAN(RADIANS(sweepLE))-L_fus/2+c_tip -> 4.0062695 | AD7: =b_w/2 -> 17.70322 | AE7: =z_w0+b_w/2*TAN(RADIANS(dihedral)) -> 0.35427609 | AG7: =IF(N_eng=4,eta_out,IF(N_eng=3,0,AG5)) -> 0.34 | AH7: =AG7*b_w/2 -> 6.0190949 | AI7: =IF(AG7=0,L_fus-tail_len-0.2*L_nac,x_wLE0+ABS(AH7)*TAN(RADIANS(sweepLE))-0.8*L_nac) -> 10.385503 | AJ7: =IF(AG7=0,z_VT0+0.55*D_nac,z_w0+ABS(AH7)*TAN(RADIANS(dihedral))-0.6*D_nac) -> -2.0075068 | AL7: =AI5+1*L_nac-L_fus/2 -> -3.1011787 | AM7: =AH5+1*D_nac/2 -> 7.1353903 | AN7: =AJ5+1*D_nac/2 -> -0.8912115 | AP7: =x_main-L_fus/2+-0.86603*D_tyre/2 -> -0.80361309 | AQ7: =-h_cg+D_tyre/2+0.5*D_tyre/2 -> -2.7989342 | AV7: 2 | AW7: =MIN(AV7,n_SA-1) -> 2 | AX7: =-w_cabin/2+0.025+(1)*(AW7*seat_w+aisle_w*((AW7>=aisle1)+(AW7>=aisle2))) -> -0.78 | AY7: =MAX(0,MIN(2,n_rows-1)) -> 2 | AZ7: =x_eco0+AY7*(seat_pitch) -> 8.12 | BA7: =nose_len+1*L_cabin -> 29.25 | BB7: =1*w_cabin/2 -> 1.865 | BC7: =BA7-L_fus/2 -> 11.43952 | BD7: =T7-L_fus/2 -> -17.53048 | BE7: =U7*1 -> 0.73178344 | BF7: =V7+U7*0 -> -0.37774247 | BG7: =BD7*COS(RADIANS(view_az))+BE7*SIN(RADIANS(view_az)) -> -12.958745 | BH7: =BF7*COS(RADIANS(view_el))+(BE7*COS(RADIANS(view_az))-BD7*SIN(RADIANS(view_az)))*SIN(RADIANS(view_el)) -> 4.656781 | BK7: ="Horizontal tail: S = "&TEXT(S_HT,"0.0")&" m2, b = "&TEXT(b_HT,"0.0")&" m" -> Horizontal tail: S = 34.4 m2, b = 12.4 m | BM7: =$AZ$5 -> 6.5 | BN7: =$AX$5+seat_w*($AY$5*n_SA+$AW$5<pax_e) -> -1.31 | BO7: =BM7-L_fus/2 -> -11.31048 | BQ7: =0.5*nose_len+1*MIN(0.6,0.2*nose_len) -> 2.6 | BR7: =-1*MIN(0.55,0.2*d_fus)+1*MIN(0.5,0.25*d_fus)/2 -> -0.3 | BT7: 2 | BU7: =MIN(BT7,n_lav-1) -> 2 | BV7: =IF(BU7<n_lav_front,1,0) -> 0 | BW7: =IF(BV7=1,BU7,BU7-n_lav_front) -> 1 | BX7: =IF(BV7=1,nose_len,x_seat_end+door_len)+INT(BW7/lav_slots)*lav_len -> 28.25 | BY7: =CHOOSE(MOD(BW7,lav_slots)+1,-w_cabin/2,w_cabin/2-lav_w,-lav_w/2) -> 0.865 | CA7: =$BX$5+1*lav_len -> 5 | CB7: =$BY$5+1*lav_w -> -0.865 | CE7: =2/24*CLmax_c -> 0.125 | CF7: =CD_0+K_ind*CE7^2 -> 0.01865442 | CG7: =CE7/CF7 -> 6.7008248 | CH7: =2/24*CLmaxTO -> 0.175 | CI7: =CD_0+dCD0_f2+K_ind*CH7^2 -> 0.03719933 | CJ7: =CH7/CI7 -> 4.7043858 | CK7: =2/24*CLmaxL -> 0.225 | CL7: =CD_0+dCD0_fMA+dCD0_gear+K_ind*CK7^2 -> 0.060001978 | CM7: =CK7/CL7 -> 3.7498764 | CR7: =2/28*h_abs -> 818.95834 | CS7: =IF(CR7<=11000,288.15-0.0065*CR7,216.65) -> 282.82677 | CT7: =IF(CR7<=11000,rho_SL*(CS7/288.15)^4.25588,0.36392*EXP(-(CR7-11000)/6341.62)) -> 1.1315442 | CU7: =SQRT(1.4*287.053*CS7) -> 337.13615 | CV7: =TW_p*(CT7/rho_SL)^lapse_n -> 0.26156809 | CW7: =MIN(M_MO*CU7,SQRT(CV7*WS_p*(1+SQRT(1+3/(LD_max^2*CV7^2)))/(3*CT7*CD_0))) -> 209.55673 | CX7: =MAX(0,CW7*(CV7-0.5*CT7*CW7^2*CD_0/WS_p-K_ind*WS_p/(0.5*CT7*CW7^2))) -> 34.201279 | CY7: =IF(CR7>=h_cr,0,(MIN(CR8,h_cr)-CR7)/MAX(0.05,(CX7+CX8)/2)) -> 12.352792 | CZ7: =MAX(0,CV7^2-4*CD_0*K_ind) -> 0.065402296 | DA7: =MAX(SQRT(2*WS_p/(CT7*CLmax_c)),SQRT(2*WS_p*(CV7-SQRT(CZ7))/(2*CD_0)/CT7)) -> 76.526904 | DB7: =MAX(DA7,MIN(M_MO*CU7,SQRT(2*WS_p*(CV7+SQRT(CZ7))/(2*CD_0)/CT7))) -> 276.45164 | DC7: =DA7/CU7 -> 0.2269911 | DD7: =DB7/CU7 -> 0.82 | DJ7: =2/10*V_A -> 23.975063 | DK7: =(2/10*V_A/V_S1)^2 -> 0.1 | DL7: =V_D -> 160.94389 | DM7: =n_gD -> 1.5233948 | DN7: =V_D -> 160.94389 | DO7: =2-n_gD -> 0.4766052 | DQ7: =Design!$D$443 -> 0.45775399 | DR7: =Design!$B$443 -> 71061.951 | DX7: =d_fus/2*0.86603 -> 1.7242008 | DY7: =d_fus/2*0.5 -> 0.9954625 | DZ7: =b_w/2 -> 17.70322 | EA7: =z_w0+b_w/2*TAN(RADIANS(dihedral)) -> 0.35427609 | EB7: =$AH$5+D_nac/2*0.5 -> 6.5772426 | EC7: =$AJ$5+D_nac/2*0.86603 -> -1.0407616 | ED7: =-track/2+-1*2.2*w_tyre/2 -> -4.0039099 | EE7: =-h_cg+D_tyre -> -2.5108116 | EG7: =d_fus/2*0.93969 -> 1.8708523 | EH7: =d_fus/2*0.34202 -> 0.68093617 | EI7: =w_cabin/2*0.93969 -> 1.7525218 | EJ7: =w_cabin/2*0.34202 -> 0.6378673 | EM7: =$AX$5+0.95*seat_w -> -1.3365 | EN7: =z_floor+1.1 -> 0.5 | ER7: =IF(1<n_door,x_door_f+IF(n_door>1,1/(n_door-1),0)*(x_door_r-x_door_f),IF(1<n_door+n_overwing,x_ac_w+(1-n_door-(n_overwing-1)/2)*seat_pitch,x_door_f)) -> 27.5 | ES7: =-1*w_cabin/2 -> -1.865 | ET7: =x_seat0-door_len+1*0.6 -> 5.6 | EU7: =w_cabin/2-gal_w+1*gal_w -> 1.865 | EW7: Payload x 0.9 | EX7: =W_pl*0.9 -> 12825 | EY7: =fuel_frac -> 0.29670802 | EZ7: =A_emp -> 0.97 | FA7: =MTOW_frac -> 71061.951 | FB7: =IF(1-$EY7-$EZ7*FA7^C_emp>0.02,(W_crew+$EX7)/(1-$EY7-$EZ7*FA7^C_emp),FA7) -> 64180.314 | FC7: =IF(1-$EY7-$EZ7*FB7^C_emp>0.02,(W_crew+$EX7)/(1-$EY7-$EZ7*FB7^C_emp),FB7) -> 65137.162 | FD7: =IF(1-$EY7-$EZ7*FC7^C_emp>0.02,(W_crew+$EX7)/(1-$EY7-$EZ7*FC7^C_emp),FC7) -> 64996.005 | FE7: =IF(1-$EY7-$EZ7*FD7^C_emp>0.02,(W_crew+$EX7)/(1-$EY7-$EZ7*FD7^C_emp),FD7) -> 65016.652 | FF7: =IF(1-$EY7-$EZ7*FE7^C_emp>0.02,(W_crew+$EX7)/(1-$EY7-$EZ7*FE7^C_emp),FE7) -> 65013.628 | FG7: =IF(1-$EY7-$EZ7*FF7^C_emp>0.02,(W_crew+$EX7)/(1-$EY7-$EZ7*FF7^C_emp),FF7) -> 65014.071 | FH7: =IF(1-$EY7-$EZ7*FG7^C_emp>0.02,(W_crew+$EX7)/(1-$EY7-$EZ7*FG7^C_emp),FG7) -> 65014.006 | FI7: =IF(1-$EY7-$EZ7*FH7^C_emp>0.02,(W_crew+$EX7)/(1-$EY7-$EZ7*FH7^C_emp),FH7) -> 65014.016 | ... FY7: =IF(1-$EY7-$EZ7*FX7^C_emp>0.02,(W_crew+$EX7)/(1-$EY7-$EZ7*FX7^C_emp),FX7) -> 65014.015 | GA7: Bombardier CRJ900 | GB7: 90 | GC7: 38330 | GD7: 21845 | GE7: 71.1 | GF7: 24.85 | GG7: 36.4 | GH7: 59.4 | GI7: 2 | GJ7: 2880 | GK7: =ABS(LN(GC7/MTOW))+ABS(LN(MAX(1,GB7)/MAX(1,PaxTyp))) -> 1.1281448 | GZ7: wing LE at centreline | HA7: =HA6-y_MAC*TAN(RADIANS(sweepLE)) -> 8.5642791 | HB7: =HB6-y_MAC*TAN(RADIANS(sweepLE)) -> 14.263633 | HF7: =HR6 -> 72362.332 | HG7: =HF7*grav/WS_des -> 134.37435 | HH7: =SQRT(AR_*HG7) -> 35.728928 | HI7: =2*HG7/(HH7*(1+taper)) -> 6.0175037 | HJ7: =2/3*HI7*(1+taper+taper^2)/(1+taper) -> 4.2122526 | HK7: =49*MAX(0.5*HG7,HG7-d_fus*HI7*(1-(1-taper)*d_fus/(2*HH7))) -> 5459.3314 | HL7: =27*(c_HT*HJ7*HG7/L_tail+c_VT*HH7*HG7/L_tail) -> 1681.2236 | HM7: =24*S_wet_fus -> 9147.0379 | HN7: =0.043*HF7 -> 3111.5803 | HO7: =1.3*N_eng*14.7*(TW_des*HF7*grav/N_eng/1000)^1.1*EXP(-0.045*BPR) -> 4665.7886 | HP7: =0.17*HF7 -> 12301.596 | HQ7: =SUM(HK7:HP7) -> 36366.558 | HR7: =IF(fuel_frac<0.95,MIN(100*MTOW_frac,(W_crew+W_pl+HQ7)/(1-fuel_frac)),HF7) -> 72632.079 | HT7: 2 | HU7: =MIN(HT7,n_SA_b-1) -> 2 | HV7: =-w_cabin/2+0.025+(n_rows_b>0)*(HU7*seat_w_b+aisle_w*((HU7>=aisle1_b)+(HU7>=aisle2_b))) -> -1.84 | HW7: =MAX(0,MIN(2,n_rows_b-1)) -> 0 | HX7: =x_seat0+HW7*(bus_pitch*(n_rows_b>0)) -> 6.5 | HY7: =$HX$5 -> 6.5 | HZ7: =$HV$5+seat_w_b*($HW$5*n_SA_b+$HU$5<pax_b) -> -1.84 | IA7: =HY7-L_fus/2 -> -11.31048 | IC7: =x_wLE0+(0.85*b_w/2)*TAN(RADIANS(sweepLE))-L_fus/2+0.65*c_root*(1-(1-taper)*2*(0.85*b_w/2)/b_w) -> 2.4475009 | ID7: =1*0.85*b_w/2 -> 15.047737
A8: =13/50 -> 0.26 | B8: =A8*WS_max -> 1447.2352 | C8: =B8/grav -> 147.57692 | D8: =TO_slope*B8 -> 0.07474675 | E8: =TW_2 -> 0.21941554 | F8: =TW_MA -> 0.21104328 | G8: =beta_cr/alpha_cr*(q_cr*CD_0/(beta_cr*B8)+K_ind*beta_cr*B8/q_cr+ROC_cr/V_cr) -> 0.62581994 | H8: =MAX(D8:G8) -> 0.62581994 | K8: Design W/S | L8: Design T/W | S8: nose 0.15 | T8: =0.15*nose_len -> 0.6 | U8: =d_fus/2*SQRT(1-(1-0.15)^2) -> 1.0487848 | V8: =-0.3*(d_fus/2-U8) -> -0.28264205 | X8: =T8-L_fus/2 -> -17.21048 | Y8: =V8+1*U8 -> 0.76614277 | Z8: =1*U8 -> 1.0487848 | AA8: =T8 -> 0.6 | AC8: =x_wLE0+c_root-L_fus/2 -> -1.3416567 | AD8: 0 | AE8: =z_w0 -> -1.194555 | AG8: =IF(N_eng=4,-eta_out,AG6) -> -0.34 | AH8: =AG8*b_w/2 -> -6.0190949 | AI8: =IF(AG8=0,L_fus-tail_len-0.2*L_nac,x_wLE0+ABS(AH8)*TAN(RADIANS(sweepLE))-0.8*L_nac) -> 10.385503 | AJ8: =IF(AG8=0,z_VT0+0.55*D_nac,z_w0+ABS(AH8)*TAN(RADIANS(dihedral))-0.6*D_nac) -> -2.0075068 | AL8: =AI5+0*L_nac-L_fus/2 -> -7.4249768 | AM8: =AH5+1*D_nac/2 -> 7.1353903 | AN8: =AJ5+1*D_nac/2 -> -0.8912115 | AP8: =x_main-L_fus/2+-1*D_tyre/2 -> -0.88081266 | AQ8: =-h_cg+D_tyre/2+0*D_tyre/2 -> -3.0870568 | AV8: 3 | AW8: =MIN(AV8,n_SA-1) -> 3 | AX8: =-w_cabin/2+0.025+(1)*(AW8*seat_w+aisle_w*((AW8>=aisle1)+(AW8>=aisle2))) -> 0.25 | AY8: =MAX(0,MIN(3,n_rows-1)) -> 3 | AZ8: =x_eco0+AY8*(seat_pitch) -> 8.93 | BA8: =nose_len+0*L_cabin -> 4 | BB8: =1*w_cabin/2 -> 1.865 | BC8: =BA8-L_fus/2 -> -13.81048 | BD8: =T8-L_fus/2 -> -17.21048 | BE8: =U8*1 -> 1.0487848 | BF8: =V8+U8*0 -> -0.28264205 | BG8: =BD8*COS(RADIANS(view_az))+BE8*SIN(RADIANS(view_az)) -> -12.509847 | BH8: =BF8*COS(RADIANS(view_el))+(BE8*COS(RADIANS(view_az))-BD8*SIN(RADIANS(view_az)))*SIN(RADIANS(view_el)) -> 4.7586695 | BK8: ="Vertical tail: S = "&TEXT(S_VT,"0.0")&" m2, h = "&TEXT(b_VT,"0.0")&" m" -> Vertical tail: S = 26.2 m2, h = 6.7 m | BM8: =$AZ$5+1*(seat_pitch)*($AY$5*n_SA+$AW$5<pax_e) -> 7.31 | BN8: =$AX$5+seat_w*($AY$5*n_SA+$AW$5<pax_e) -> -1.31 | BO8: =BM8-L_fus/2 -> -10.50048 | BQ8: =0.5*nose_len+0*MIN(0.6,0.2*nose_len) -> 2 | BR8: =-1*MIN(0.55,0.2*d_fus)+1*MIN(0.5,0.25*d_fus)/2 -> -0.3 | BT8: 3 | BU8: =MIN(BT8,n_lav-1) -> 2 | BV8: =IF(BU8<n_lav_front,1,0) -> 0 | BW8: =IF(BV8=1,BU8,BU8-n_lav_front) -> 1 | BX8: =IF(BV8=1,nose_len,x_seat_end+door_len)+INT(BW8/lav_slots)*lav_len -> 28.25 | BY8: =CHOOSE(MOD(BW8,lav_slots)+1,-w_cabin/2,w_cabin/2-lav_w,-lav_w/2) -> 0.865 | CA8: =$BX$5+0*lav_len -> 4 | CB8: =$BY$5+1*lav_w -> -0.865 | CE8: =3/24*CLmax_c -> 0.1875 | CF8: =CD_0+K_ind*CE8^2 -> 0.019472445 | CG8: =CE8/CF8 -> 9.6289911 | CH8: =3/24*CLmaxTO -> 0.2625 | CI8: =CD_0+dCD0_f2+K_ind*CH8^2 -> 0.038802659 | CJ8: =CH8/CI8 -> 6.7650003 | CK8: =3/24*CLmaxL -> 0.3375 | CL8: =CD_0+dCD0_fMA+dCD0_gear+K_ind*CK8^2 -> 0.062652379 | CM8: =CK8/CL8 -> 5.3868665 | CR8: =3/28*h_abs -> 1228.4375 | CS8: =IF(CR8<=11000,288.15-0.0065*CR8,216.65) -> 280.16516 | CT8: =IF(CR8<=11000,rho_SL*(CS8/288.15)^4.25588,0.36392*EXP(-(CR8-11000)/6341.62)) -> 1.086914 | CU8: =SQRT(1.4*287.053*CS8) -> 335.54604 | CV8: =TW_p*(CT8/rho_SL)^lapse_n -> 0.24831264 | CW8: =MIN(M_MO*CU8,SQRT(CV8*WS_p*(1+SQRT(1+3/(LD_max^2*CV8^2)))/(3*CT8*CD_0))) -> 208.66992 | CX8: =MAX(0,CW8*(CV8-0.5*CT8*CW8^2*CD_0/WS_p-K_ind*WS_p/(0.5*CT8*CW8^2))) -> 32.09615 | CY8: =IF(CR8>=h_cr,0,(MIN(CR9,h_cr)-CR8)/MAX(0.05,(CX8+CX9)/2)) -> 13.171022 | CZ8: =MAX(0,CV8^2-4*CD_0*K_ind) -> 0.058643597 | DA8: =MAX(SQRT(2*WS_p/(CT8*CLmax_c)),SQRT(2*WS_p*(CV8-SQRT(CZ8))/(2*CD_0)/CT8)) -> 78.082247 | DB8: =MAX(DA8,MIN(M_MO*CU8,SQRT(2*WS_p*(CV8+SQRT(CZ8))/(2*CD_0)/CT8))) -> 275.14776 | DC8: =DA8/CU8 -> 0.23270203 | DD8: =DB8/CU8 -> 0.82 | DJ8: =3/10*V_A -> 35.962594 | DK8: =(3/10*V_A/V_S1)^2 -> 0.225 | DQ8: =Design!$D$444 -> 0.44090084 | DR8: =Design!$B$444 -> 56811.951 | DX8: =d_fus/2*0.70711 -> 1.407803 | DY8: =d_fus/2*0.70711 -> 1.407803 | EB8: =$AH$5+D_nac/2*0 -> 6.0190949 | EC8: =$AJ$5+D_nac/2*1 -> -0.8912115 | ED8: =-track/2+-1*2.2*w_tyre/2 -> -4.0039099 | EE8: =-h_cg -> -3.663302 | EG8: =d_fus/2*0.86603 -> 1.7242008 | EH8: =d_fus/2*0.5 -> 0.9954625 | EI8: =w_cabin/2*0.86603 -> 1.6151459 | EJ8: =w_cabin/2*0.5 -> 0.9325 | EK8: =-1*SQRT(MAX(0,(w_cabin/2)^2-(-d_hold)^2)) -> -1.6847032 | EL8: =-d_hold -> -0.8 | EM8: =$AX$5+0.95*seat_w -> -1.3365 | EN8: =z_floor+0 -> -0.6 | ER8: =IF(1<n_door,x_door_f+IF(n_door>1,1/(n_door-1),0)*(x_door_r-x_door_f),IF(1<n_door+n_overwing,x_ac_w+(1-n_door-(n_overwing-1)/2)*seat_pitch,x_door_f)) -> 27.5 | ES8: =1*w_cabin/2 -> 1.865 | ET8: =x_seat0-door_len+0*0.6 -> 5 | EU8: =w_cabin/2-gal_w+1*gal_w -> 1.865 | EW8: Payload x 1.1 | EX8: =W_pl*1.1 -> 15675 | EY8: =fuel_frac -> 0.29670802 | EZ8: =A_emp -> 0.97 | FA8: =MTOW_frac -> 71061.951 | FB8: =IF(1-$EY8-$EZ8*FA8^C_emp>0.02,(W_crew+$EX8)/(1-$EY8-$EZ8*FA8^C_emp),FA8) -> 77943.587 | FC8: =IF(1-$EY8-$EZ8*FB8^C_emp>0.02,(W_crew+$EX8)/(1-$EY8-$EZ8*FB8^C_emp),FB8) -> 76924.084 | FD8: =IF(1-$EY8-$EZ8*FC8^C_emp>0.02,(W_crew+$EX8)/(1-$EY8-$EZ8*FC8^C_emp),FC8) -> 77067.329 | FE8: =IF(1-$EY8-$EZ8*FD8^C_emp>0.02,(W_crew+$EX8)/(1-$EY8-$EZ8*FD8^C_emp),FD8) -> 77047.049 | FF8: =IF(1-$EY8-$EZ8*FE8^C_emp>0.02,(W_crew+$EX8)/(1-$EY8-$EZ8*FE8^C_emp),FE8) -> 77049.917 | FG8: =IF(1-$EY8-$EZ8*FF8^C_emp>0.02,(W_crew+$EX8)/(1-$EY8-$EZ8*FF8^C_emp),FF8) -> 77049.511 | FH8: =IF(1-$EY8-$EZ8*FG8^C_emp>0.02,(W_crew+$EX8)/(1-$EY8-$EZ8*FG8^C_emp),FG8) -> 77049.569 | FI8: =IF(1-$EY8-$EZ8*FH8^C_emp>0.02,(W_crew+$EX8)/(1-$EY8-$EZ8*FH8^C_emp),FH8) -> 77049.561 | ... FY8: =IF(1-$EY8-$EZ8*FX8^C_emp>0.02,(W_crew+$EX8)/(1-$EY8-$EZ8*FX8^C_emp),FX8) -> 77049.562 | GA8: Embraer E190 | GB8: 100 | GC8: 51800 | GD8: 28080 | GE8: 92.5 | GF8: 28.72 | GG8: 36.24 | GH8: 82.3 | GI8: 2 | GJ8: 4540 | GK8: =ABS(LN(GC8/MTOW))+ABS(LN(MAX(1,GB8)/MAX(1,PaxTyp))) -> 0.721627 | GZ8: engine CG | HA8: =IF(N_eng=2,(HA7+eta_in*b_w/2*TAN(RADIANS(sweepLE))-0.8*L_nac),IF(N_eng=4,((HA7+eta_in*b_w/2*TAN(RADIANS(sweepLE))-0.8*L_nac)+(HA7+eta_out*b_w/2*TAN(RADIANS(sweepLE))-0.8*L_nac))/2,(2*(HA7+eta_in*b_w/2*TAN(RADIANS(sweepLE))-0.8*L_nac)+L_fus-tail_len-0.2*L_nac)/3))+0.45*L_nac -> 10.389858 | HB8: =IF(N_eng=2,(HB7+eta_in*b_w/2*TAN(RADIANS(sweepLE))-0.8*L_nac),IF(N_eng=4,((HB7+eta_in*b_w/2*TAN(RADIANS(sweepLE))-0.8*L_nac)+(HB7+eta_out*b_w/2*TAN(RADIANS(sweepLE))-0.8*L_nac))/2,(2*(HB7+eta_in*b_w/2*TAN(RADIANS(sweepLE))-0.8*L_nac)+L_fus-tail_len-0.2*L_nac)/3))+0.45*L_nac -> 16.089212 | HF8: =HR7 -> 72632.079 | HG8: =HF8*grav/WS_des -> 134.87526 | HH8: =SQRT(AR_*HG8) -> 35.79546 | HI8: =2*HG8/(HH8*(1+taper)) -> 6.028709 | HJ8: =2/3*HI8*(1+taper+taper^2)/(1+taper) -> 4.2200963 | HK8: =49*MAX(0.5*HG8,HG8-d_fus*HI8*(1-(1-taper)*d_fus/(2*HH8))) -> 5481.6897 | HL8: =27*(c_HT*HJ8*HG8/L_tail+c_VT*HH8*HG8/L_tail) -> 1690.6331 | HM8: =24*S_wet_fus -> 9147.0379 | HN8: =0.043*HF8 -> 3123.1794 | HO8: =1.3*N_eng*14.7*(TW_des*HF8*grav/N_eng/1000)^1.1*EXP(-0.045*BPR) -> 4684.9242 | HP8: =0.17*HF8 -> 12347.453 | HQ8: =SUM(HK8:HP8) -> 36474.918 | HR8: =IF(fuel_frac<0.95,MIN(100*MTOW_frac,(W_crew+W_pl+HQ8)/(1-fuel_frac)),HF8) -> 72786.154 | HT8: 3 | HU8: =MIN(HT8,n_SA_b-1) -> 3 | HV8: =-w_cabin/2+0.025+(n_rows_b>0)*(HU8*seat_w_b+aisle_w*((HU8>=aisle1_b)+(HU8>=aisle2_b))) -> -1.84 | HW8: =MAX(0,MIN(3,n_rows_b-1)) -> 0 | HX8: =x_seat0+HW8*(bus_pitch*(n_rows_b>0)) -> 6.5 | HY8: =$HX$5+1*(bus_pitch*(n_rows_b>0))*($HW$5*n_SA_b+$HU$5<pax_b) -> 6.5 | HZ8: =$HV$5+seat_w_b*($HW$5*n_SA_b+$HU$5<pax_b) -> -1.84 | IA8: =HY8-L_fus/2 -> -11.31048 | IC8: =x_wLE0+(d_fus/2)*TAN(RADIANS(sweepLE))-L_fus/2+0.65*c_root*(1-(1-taper)*2*(d_fus/2)/b_w) -> -2.6512994 | ID8: =1*d_fus/2 -> 1.990925
A9: =14/50 -> 0.28 | B9: =A9*WS_max -> 1558.561 | C9: =B9/grav -> 158.92899 | D9: =TO_slope*B9 -> 0.080496501 | E9: =TW_2 -> 0.21941554 | F9: =TW_MA -> 0.21104328 | G9: =beta_cr/alpha_cr*(q_cr*CD_0/(beta_cr*B9)+K_ind*beta_cr*B9/q_cr+ROC_cr/V_cr) -> 0.58666542 | H9: =MAX(D9:G9) -> 0.58666542 | K9: =WS_des -> 5281.0085 | L9: =TW_des -> 0.27275334 | S9: nose 0.30 | T9: =0.3*nose_len -> 1.2 | U9: =d_fus/2*SQRT(1-(1-0.3)^2) -> 1.4218048 | V9: =-0.3*(d_fus/2-U9) -> -0.17073605 | X9: =T9-L_fus/2 -> -16.61048 | Y9: =V9+1*U9 -> 1.2510688 | Z9: =1*U9 -> 1.4218048 | AA9: =T9 -> 1.2 | AC9: =x_wLE0+b_w/2*TAN(RADIANS(sweepLE))-L_fus/2+c_tip -> 4.0062695 | AD9: =-b_w/2 -> -17.70322 | AE9: =z_w0+b_w/2*TAN(RADIANS(dihedral)) -> 0.35427609 | AL9: =AI5+0*L_nac-L_fus/2 -> -7.4249768 | AM9: =AH5+-1*D_nac/2 -> 4.9027996 | AN9: =AJ5+-1*D_nac/2 -> -3.1238022 | AP9: =x_main-L_fus/2+-0.86603*D_tyre/2 -> -0.80361309 | AQ9: =-h_cg+D_tyre/2+-0.5*D_tyre/2 -> -3.3751794 | AV9: 4 | AW9: =MIN(AV9,n_SA-1) -> 4 | AX9: =-w_cabin/2+0.025+(1)*(AW9*seat_w+aisle_w*((AW9>=aisle1)+(AW9>=aisle2))) -> 0.78 | AY9: =MAX(0,MIN(4,n_rows-1)) -> 4 | AZ9: =x_eco0+AY9*(seat_pitch) -> 9.74 | BA9: =nose_len+0*L_cabin -> 4 | BB9: =-1*w_cabin/2 -> -1.865 | BC9: =BA9-L_fus/2 -> -13.81048 | BD9: =T9-L_fus/2 -> -16.61048 | BE9: =U9*1 -> 1.4218048 | BF9: =V9+U9*0 -> -0.17073605 | BG9: =BD9*COS(RADIANS(view_az))+BE9*SIN(RADIANS(view_az)) -> -11.810447 | BH9: =BF9*COS(RADIANS(view_el))+(BE9*COS(RADIANS(view_az))-BD9*SIN(RADIANS(view_az)))*SIN(RADIANS(view_el)) -> 4.8178616 | BK9: =N_eng&" engines: "&TEXT(T_eng/1000,"0")&" kN each, nacelle "&TEXT(L_nac,"0.0")&" x "&TEXT(D_nac,"0.0")&" m" -> 2 engines: 95 kN each, nacelle 4.3 x 2.2 m | BM9: =$AZ$5+0.8*(seat_pitch)*($AY$5*n_SA+$AW$5<pax_e) -> 7.148 | BN9: =$AX$5+seat_w*($AY$5*n_SA+$AW$5<pax_e) -> -1.31 | BO9: =BM9-L_fus/2 -> -10.66248 | BQ9: =0.5*nose_len+0*MIN(0.6,0.2*nose_len) -> 2 | BR9: =-1*MIN(0.55,0.2*d_fus)+-1*MIN(0.5,0.25*d_fus)/2 -> -0.8 | BT9: 4 | BU9: =MIN(BT9,n_lav-1) -> 2 | BV9: =IF(BU9<n_lav_front,1,0) -> 0 | BW9: =IF(BV9=1,BU9,BU9-n_lav_front) -> 1 | BX9: =IF(BV9=1,nose_len,x_seat_end+door_len)+INT(BW9/lav_slots)*lav_len -> 28.25 | BY9: =CHOOSE(MOD(BW9,lav_slots)+1,-w_cabin/2,w_cabin/2-lav_w,-lav_w/2) -> 0.865 | CA9: =$BX$5+0*lav_len -> 4 | CB9: =$BY$5+0*lav_w -> -1.865 | CE9: =4/24*CLmax_c -> 0.25 | CF9: =CD_0+K_ind*CE9^2 -> 0.02061768 | CG9: =CE9/CF9 -> 12.125516 | CH9: =4/24*CLmaxTO -> 0.35 | CI9: =CD_0+dCD0_f2+K_ind*CH9^2 -> 0.041047319 | CJ9: =CH9/CI9 -> 8.5267444 | CK9: =4/24*CLmaxL -> 0.45 | CL9: =CD_0+dCD0_fMA+dCD0_gear+K_ind*CK9^2 -> 0.06636294 | CM9: =CK9/CL9 -> 6.7808931 | CR9: =4/28*h_abs -> 1637.9167 | CS9: =IF(CR9<=11000,288.15-0.0065*CR9,216.65) -> 277.50354 | CT9: =IF(CR9<=11000,rho_SL*(CS9/288.15)^4.25588,0.36392*EXP(-(CR9-11000)/6341.62)) -> 1.0436432 | CU9: =SQRT(1.4*287.053*CS9) -> 333.94837 | CV9: =TW_p*(CT9/rho_SL)^lapse_n -> 0.23561194 | CW9: =MIN(M_MO*CU9,SQRT(CV9*WS_p*(1+SQRT(1+3/(LD_max^2*CV9^2)))/(3*CT9*CD_0))) -> 207.81254 | CX9: =MAX(0,CW9*(CV9-0.5*CT9*CW9^2*CD_0/WS_p-K_ind*WS_p/(0.5*CT9*CW9^2))) -> 30.082651 | CY9: =IF(CR9>=h_cr,0,(MIN(CR10,h_cr)-CR9)/MAX(0.05,(CX9+CX10)/2)) -> 14.061915 | CZ9: =MAX(0,CV9^2-4*CD_0*K_ind) -> 0.052497417 | DA9: =MAX(SQRT(2*WS_p/(CT9*CLmax_c)),SQRT(2*WS_p*(CV9-SQRT(CZ9))/(2*CD_0)/CT9)) -> 79.684504 | DB9: =MAX(DA9,MIN(M_MO*CU9,SQRT(2*WS_p*(CV9+SQRT(CZ9))/(2*CD_0)/CT9))) -> 273.83766 | DC9: =DA9/CU9 -> 0.23861324 | DD9: =DB9/CU9 -> 0.82 | DJ9: =4/10*V_A -> 47.950126 | DK9: =(4/10*V_A/V_S1)^2 -> 0.4 | DQ9: =Design!$D$441 -> 0.43553093 | DR9: =Design!$B$441 -> 35727.3 | DX9: =d_fus/2*0.5 -> 0.9954625 | DY9: =d_fus/2*0.86603 -> 1.7242008 | DZ9: =-b_HT/2 -> -6.2176462 | EA9: =z_HT -> 1.194555 | EB9: =$AH$5+D_nac/2*-0.5 -> 5.4609472 | EC9: =$AJ$5+D_nac/2*0.86603 -> -1.0407616 | ED9: =-track/2+1*2.2*w_tyre/2 -> -3.0773782 | EE9: =-h_cg -> -3.663302 | EG9: =d_fus/2*0.76604 -> 1.5251282 | EH9: =d_fus/2*0.64279 -> 1.2797467 | EI9: =w_cabin/2*0.76604 -> 1.4286646 | EJ9: =w_cabin/2*0.64279 -> 1.1988033 | EK9: =1*SQRT(MAX(0,(w_cabin/2)^2-(-d_hold)^2)) -> 1.6847032 | EL9: =-d_hold -> -0.8 | EM9: =$AX$6+0.05*seat_w -> -1.2835 | EN9: =z_floor+0 -> -0.6 | ER9: =IF(2<n_door,x_door_f+IF(n_door>1,2/(n_door-1),0)*(x_door_r-x_door_f),IF(2<n_door+n_overwing,x_ac_w+(2-n_door-(n_overwing-1)/2)*seat_pitch,x_door_f)) -> 15.072319 | ES9: =-1*w_cabin/2 -> -1.865 | ET9: =x_seat0-door_len+0*0.6 -> 5 | EU9: =w_cabin/2-gal_w+0*gal_w -> 0.265 | EW9: TSFC x 0.9 | EX9: =W_pl -> 14250 | EY9: =k_res*(1-ff_fixed*EXP(-Range_km*1*1000*TSFC_s*0.9/(V_cr*LD_cr))) -> 0.2807936 | EZ9: =A_emp -> 0.97 | FA9: =MTOW_frac -> 71061.951 | FB9: =IF(1-$EY9-$EZ9*FA9^C_emp>0.02,(W_crew+$EX9)/(1-$EY9-$EZ9*FA9^C_emp),FA9) -> 65990.314 | FC9: =IF(1-$EY9-$EZ9*FB9^C_emp>0.02,(W_crew+$EX9)/(1-$EY9-$EZ9*FB9^C_emp),FB9) -> 66650.711 | FD9: =IF(1-$EY9-$EZ9*FC9^C_emp>0.02,(W_crew+$EX9)/(1-$EY9-$EZ9*FC9^C_emp),FC9) -> 66560.958 | FE9: =IF(1-$EY9-$EZ9*FD9^C_emp>0.02,(W_crew+$EX9)/(1-$EY9-$EZ9*FD9^C_emp),FD9) -> 66573.086 | FF9: =IF(1-$EY9-$EZ9*FE9^C_emp>0.02,(W_crew+$EX9)/(1-$EY9-$EZ9*FE9^C_emp),FE9) -> 66571.446 | FG9: =IF(1-$EY9-$EZ9*FF9^C_emp>0.02,(W_crew+$EX9)/(1-$EY9-$EZ9*FF9^C_emp),FF9) -> 66571.668 | FH9: =IF(1-$EY9-$EZ9*FG9^C_emp>0.02,(W_crew+$EX9)/(1-$EY9-$EZ9*FG9^C_emp),FG9) -> 66571.638 | FI9: =IF(1-$EY9-$EZ9*FH9^C_emp>0.02,(W_crew+$EX9)/(1-$EY9-$EZ9*FH9^C_emp),FH9) -> 66571.642 | ... FY9: =IF(1-$EY9-$EZ9*FX9^C_emp>0.02,(W_crew+$EX9)/(1-$EY9-$EZ9*FX9^C_emp),FX9) -> 66571.641 | GA9: Airbus A320-200 | GB9: 150 | GC9: 78000 | GD9: 42600 | GE9: 122.6 | GF9: 34.1 | GG9: 37.57 | GH9: 118 | GI9: 2 | GJ9: 6100 | GK9: =ABS(LN(GC9/MTOW))+ABS(LN(MAX(1,GB9)/MAX(1,PaxTyp))) -> 0.093156787 | GZ9: moment without gear | HA9: =Design!$B$427*(HA6+0.4*MAC)+Design!$B$428*(HA5*L_fus+L_tail+0.15*MAC_HT)+Design!$B$429*(HA5*L_fus+L_tail+0.15*MAC_VT)+Design!$B$430*0.45*L_fus+Design!$B$433*HA8+Design!$B$434*0.45*L_fus -> 512805.29 | HB9: =Design!$B$427*(HB6+0.4*MAC)+Design!$B$428*(HB5*L_fus+L_tail+0.15*MAC_HT)+Design!$B$429*(HB5*L_fus+L_tail+0.15*MAC_VT)+Design!$B$430*0.45*L_fus+Design!$B$433*HB8+Design!$B$434*0.45*L_fus -> 578697.55 | HF9: =HR8 -> 72786.154 | HG9: =HF9*grav/WS_des -> 135.16137 | HH9: =SQRT(AR_*HG9) -> 35.833406 | HI9: =2*HG9/(HH9*(1+taper)) -> 6.0351 | HJ9: =2/3*HI9*(1+taper+taper^2)/(1+taper) -> 4.22457 | HK9: =49*MAX(0.5*HG9,HG9-d_fus*HI9*(1-(1-taper)*d_fus/(2*HH9))) -> 5494.4622 | HL9: =27*(c_HT*HJ9*HG9/L_tail+c_VT*HH9*HG9/L_tail) -> 1696.0154 | HM9: =24*S_wet_fus -> 9147.0379 | HN9: =0.043*HF9 -> 3129.8046 | HO9: =1.3*N_eng*14.7*(TW_des*HF9*grav/N_eng/1000)^1.1*EXP(-0.045*BPR) -> 4695.8574 | HP9: =0.17*HF9 -> 12373.646 | HQ9: =SUM(HK9:HP9) -> 36536.824 | HR9: =IF(fuel_frac<0.95,MIN(100*MTOW_frac,(W_crew+W_pl+HQ9)/(1-fuel_frac)),HF9) -> 72874.177 | HT9: 4 | HU9: =MIN(HT9,n_SA_b-1) -> 3 | HV9: =-w_cabin/2+0.025+(n_rows_b>0)*(HU9*seat_w_b+aisle_w*((HU9>=aisle1_b)+(HU9>=aisle2_b))) -> -1.84 | HW9: =MAX(0,MIN(4,n_rows_b-1)) -> 0 | HX9: =x_seat0+HW9*(bus_pitch*(n_rows_b>0)) -> 6.5 | HY9: =$HX$5+0.8*(bus_pitch*(n_rows_b>0))*($HW$5*n_SA_b+$HU$5<pax_b) -> 6.5 | HZ9: =$HV$5+seat_w_b*($HW$5*n_SA_b+$HU$5<pax_b) -> -1.84 | IA9: =HY9-L_fus/2 -> -11.31048 | IC9: =x_wLE0+(d_fus/2)*TAN(RADIANS(sweepLE))-L_fus/2+0.15*c_root*(1-(1-taper)*2*(d_fus/2)/b_w) -> -5.3814091 | ID9: =1*d_fus/2 -> 1.990925
